Workbook

Sheet Líneas
A1: ID Línea | B1: Nombre Línea | C1: Tipo Servicio | D1: Scope | E1: Operador | F1: Propietario | G1: Color | H1: CCAA_de_paso | I1: Provincias_de_paso | J1: Estaciones_de_paso_Nombres | K1: Estaciones_IDs | L1: Coordenadas_OSM | M1: Ruta_GEOJSON
A2: 10 | B2: AVE Madrid - Málaga | C2: AVE | D2: ave | E2: Renfe | F2: Renfe | G2: #EC1C24 | H2: Madrid; Andalucía | I2: Madrid; Córdoba; Málaga | J2: Madrid-Puerta de Atocha; Córdoba; Puente Genil-Herrera; Antequera-Santa Ana; Málaga-María Zambrano | K2: EST-MADRIDPUERTADEATOCHA;EST-CORDOBA;EST-PUENTEGENILHERRERA;EST-ANTEQUERASANTAANA;EST-MALAGAMARIAZAMBRANO | L2: 40.40697,-3.68860; 38.25524,-4.57142; 37.35892,-4.82223; 37.07017,-4.71971; 43.39830,-4.01003 | M2: 10.geojson
A3: 11 | B3: AVE Madrid - Granada | C3: AVE | D3: ave | E3: Renfe | F3: Renfe | G3: #EC1C24 | H3: Madrid; Andalucía | I3: Madrid; Córdoba; Málaga; Granada | J3: Madrid-Puerta de Atocha; Córdoba; Antequera-Santa Ana; Loja; Granada | K3: EST-MADRIDPUERTADEATOCHA;EST-CORDOBA;EST-ANTEQUERASANTAANA;EST-LOJA;EST-GRANADA | L3: 40.40697,-3.68860; 38.25524,-4.57142; 37.07017,-4.71971; 37.17511,-4.13567; 37.18369,-3.60863 | M3: 11.geojson
A4: 12 | B4: AVE Madrid - Galicia (A Coruña) | C4: AVE | D4: ave | E4: Renfe | F4: Renfe | G4: #EC1C24 | H4: Madrid; Castilla y León; Galicia | I4: Madrid; Segovia; Valladolid; Zamora; Ourense; A Coruña | J4: Madrid-Chamartín; Segovia-Guiomar; Medina del Campo AV; Zamora; Ourense; Santiago de Compostela; A Coruña | K4: EST-MADRIDCHAMARTIN;EST-SEGOVIAGUIOMAR;EST-MEDINADELCAMPOAV;EST-ZAMORA;EST-OURENSE;EST-SANTIAGODECOMPOSTELA;EST-ACORUNA | L4: 40.47395,-3.68271; 40.91014,-4.09476; 41.29133,-4.92299; 41.51600,-5.73978; 42.35069,-7.87255; 42.87044,-8.54520; 43.35037,-8.41215 | M4: 12.geojson
A5: 13 | B5: AVE Madrid - Galicia (Vigo) | C5: AVE | D5: ave | E5: Renfe | F5: Renfe | G5: #EC1C24 | H5: Madrid; Castilla y León; Galicia | I5: Madrid; Segovia; Valladolid; Zamora; Ourense; A Coruña; Pontevedra | J5: Madrid-Chamartín; Segovia-Guiomar; Medina del Campo AV; Zamora; Ourense; Santiago de Compostela; Pontevedra; Vigo-Urzaiz | K5: EST-MADRIDCHAMARTIN;EST-SEGOVIAGUIOMAR;EST-MEDINADELCAMPOAV;EST-ZAMORA;EST-OURENSE;EST-SANTIAGODECOMPOSTELA;EST-PONTEVEDRA;EST-VIGOURZAIZ | L5: 40.47395,-3.68271; 40.91014,-4.09476; 41.29133,-4.92299; 41.51600,-5.73978; 42.35069,-7.87255; 42.87044,-8.54520; 42.42168,-8.63540; 42.23496,-8.71190 | M5: 13.geojson
A6: 14 | B6: Alvia Madrid - Cádiz | C6: Larga Distancia | D6: long_distance | E6: Renfe | F6: Renfe | G6: #5F259F | H6: Madrid; Castilla-La Mancha; Andalucía | I6: Madrid; Ciudad Real; Córdoba; Sevilla; Cádiz | J6: Madrid-Puerta de Atocha; Ciudad Real; Puertollano; Córdoba; Sevilla-Santa Justa; Jerez de la Frontera; El Puerto de Santa María; San Fernando-Bahía Sur; Cádiz | K6: EST-MADRIDPUERTADEATOCHA;EST-CIUDADREAL;EST-PUERTOLLANO;EST-CORDOBA;EST-SEVILLASANTAJUSTA;EST-JEREZDELAFRONTERA;EST-ELPUERTODESANTAMARIA;EST-SANFERNANDOBAHIASUR;EST-CADIZ | L6: 40.40697,-3.68860; 38.98487,-3.91314; 38.69129,-4.11194; 38.25524,-4.57142; 40.41777,-3.69995; 36.67981,-6.12610; 36.60420,-6.21700; 36.46792,-6.20688; 37.38296,-5.98418 | M6: 14.geojson
A7: 15 | B7: Alvia Madrid - Huelva | C7: Larga Distancia | D7: long_distance | E7: Renfe | F7: Renfe | G7: #5F259F | H7: Madrid; Andalucía | I7: Madrid; Córdoba; Huelva | J7: Madrid-Puerta de Atocha; Córdoba; La Palma del Condado; Huelva | K7: EST-MADRIDPUERTADEATOCHA;EST-CORDOBA;EST-LAPALMADELCONDADO;EST-HUELVA | L7: 40.40697,-3.68860; 38.25524,-4.57142; 37.39079,-6.55436; 37.25262,-6.94485 | M7: 15.geojson
A8: 16 | B8: Alvia Madrid - Gijón (con Segovia) | C8: Larga Distancia | D8: long_distance | E8: Renfe | F8: Renfe | G8: #5F259F | H8: Madrid; Castilla y León; Principado de Asturias | I8: Madrid; Segovia; Valladolid; Palencia; León; Asturias | J8: Madrid-Chamartín-Clara Campoamor; Segovia-Guiomar; Valladolid-Campo Grande; Palencia; León; Pola de Lena; Mieres-Puente; Oviedo; Gijón | K8: EST-MADRIDCHAMARTINCLARACAMPOAMOR;EST-SEGOVIAGUIOMAR;EST-VALLADOLIDCAMPOGRANDE;EST-PALENCIA;EST-LEON;EST-POLADELENA;EST-MIERESPUENTE;EST-OVIEDO;EST-GIJON | L8: 40.47206,-3.68226; 40.91014,-4.09476; 41.64334,-4.72720; 42.01573,-4.53386; 42.40550,-6.52214; 43.15865,-5.83113; 43.25004,-5.78239; 43.36636,-5.85487; 43.53773,-5.67563 | M8: 16.geojson
A9: 17 | B9: Alvia Madrid - Santander | C9: Larga Distancia | D9: long_distance | E9: Renfe | F9: Renfe | G9: #5F259F | H9: Madrid; Castilla y León; Cantabria | I9: Madrid; Segovia; Valladolid; Palencia; Cantabria | J9: Madrid-Chamartín-Clara Campoamor; Segovia-Guiomar; Valladolid-Campo Grande; Palencia; Aguilar de Campoo; Reinosa; Torrelavega; Santander | K9: EST-MADRIDCHAMARTINCLARACAMPOAMOR;EST-SEGOVIAGUIOMAR;EST-VALLADOLIDCAMPOGRANDE;EST-PALENCIA;EST-AGUILARDECAMPOO;EST-REINOSA;EST-TORRELAVEGA;EST-SANTANDER | L9: 40.47206,-3.68226; 40.91014,-4.09476; 41.64334,-4.72720; 42.01573,-4.53386; 42.78527,-4.23375; 42.99434,-4.14103; 43.32744,-4.04246; 43.45830,-3.81102 | M9: 17.geojson
A10: 18 | B10: Alvia Madrid - Bilbao | C10: Larga Distancia | D10: long_distance | E10: Renfe | F10: Renfe | G10: #0071BC | H10: Madrid; Castilla y León; País Vasco | I10: Madrid; Segovia; Valladolid; Burgos; Álava; Bizkaia | J10: Madrid-Chamartín-Clara Campoamor; Segovia-Guiomar; Valladolid-Campo Grande; Burgos-Rosa de Lima; Miranda de Ebro; Llodio; Bilbao-Abando | K10: EST-MADRIDCHAMARTINCLARACAMPOAMOR;EST-SEGOVIAGUIOMAR;EST-VALLADOLIDCAMPOGRANDE;EST-BURGOSROSADELIMA;EST-MIRANDADEEBRO;EST-LLODIO;EST-BILBAOABANDO | L10: 40.47206,-3.68226; 40.91014,-4.09476; 41.64334,-4.72720; 42.37117,-3.66632; 42.69080,-2.94114; 43.14225,-2.96050; 43.26136,-2.92744 | M10: 18.geojson
A11: 19 | B11: Alvia Madrid - Irún | C11: Larga Distancia | D11: long_distance | E11: Renfe | F11: Renfe | G11: #0071BC | H11: Madrid; Castilla y León; País Vasco | I11: Madrid; Segovia; Valladolid; Burgos; Álava; Gipuzkoa | J11: Madrid-Chamartín-Clara Campoamor; Segovia-Guiomar; Valladolid-Campo Grande; Burgos-Rosa de Lima; Miranda de Ebro; Vitoria-Gasteiz; Zumárraga; Tolosa; San Sebastián; Irún | K11: EST-MADRIDCHAMARTINCLARACAMPOAMOR;EST-SEGOVIAGUIOMAR;EST-VALLADOLIDCAMPOGRANDE;EST-BURGOSROSADELIMA;EST-MIRANDADEEBRO;EST-VITORIAGASTEIZ;EST-ZUMARRAGA;EST-TOLOSA;EST-SANSEBASTIAN;EST-IRUN | L11: 40.47206,-3.68226; 40.91014,-4.09476; 41.64334,-4.72720; 42.37117,-3.66632; 42.69080,-2.94114; 42.84130,-2.67270; 43.08701,-2.31988; 43.13564,-2.07914; 40.54675,-3.63460; 43.33921,-1.80058 | M11: 19.geojson
A12: 20 | B12: Alvia Madrid - Pamplona | C12: Larga Distancia | D12: long_distance | E12: Renfe | F12: Renfe | G12: #0071BC | H12: Madrid; Castilla-La Mancha; Aragón; Navarra | I12: Madrid; Guadalajara; Zaragoza; Navarra | J12: Madrid-Puerta de Atocha; Guadalajara-Yebes; Calatayud; Tudela de Navarra; Castejón de Ebro; Tafalla; Pamplona | K12: EST-MADRIDPUERTADEATOCHA;EST-GUADALAJARAYEBES;EST-CALATAYUD;EST-TUDELADENAVARRA;EST-CASTEJONDEEBRO;EST-TAFALLA;EST-PAMPLONA | L12: 40.40697,-3.68860; 40.64408,-3.18225; 41.34636,-1.63842; 42.05950,-1.59767; 42.17287,-1.69244; 42.52575,-1.67121; 42.82505,-1.66149 | M12: 20.geojson
... A390: 404 | B390: Regional 47 Valencia - Játiva - Alcoy | C390: Regional | D390: regional | E390: Renfe | F390: Renfe | G390: #008000 | H390: Comunidad Valenciana | I390: Valencia; Alicante | J390: Xàtiva; Genovés; Benigánim; Montaberner; Bufalí; Albaida; Agullent; Onteniente; Agres; Cocentaina; Alcoy | K390: EST-XATIVA; EST-GENOVES; EST-BENIGANIM; EST-MONTABERNER; EST-BUFALI; EST-ALBAIDA; EST-AGULLENT; EST-ONTENIENTE; EST-AGRES; EST-COCENTAINA; EST-ALCOY | L390: 43.28681,-5.64784; 38.99225,-0.52468; 38.97458,-0.48516; 38.93833,-0.45323; 37.97658,-1.13346; 39.33300,-0.46800; 39.41800,-0.41300; 38.84467,-0.52241; 38.83056,-0.55120; 38.79460,-0.68247; 38.79686,-0.52183; 38.74078,-0.44705; 38.70976,-0.46883 | M390: 404.geojson
A391: 405 | B391: Funicular del Tibidabo (Cuca de Llum) | C391: Funicular | D391: funicular | E391: TMB | F391: TMB | G391: #FF6600 | H391: Cataluña | I391: Barcelona | J391: Plaça del Doctor Andreu; Tibidabo | K391: EST-PLACADOCTORANDREU; EST-TIBIDABO | M391: 405.geojson
A392: 406 | B392: Funicular de la Santa Cova | C392: Funicular | D392: funicular | E392: FGC | F392: FGC | G392: #8B4513 | H392: Cataluña | I392: Barcelona | J392: Montserrat-Monestir; Santa Cova | K392: EST-MONTSERRAT; EST-SANTACOVA | M392: 406.geojson
A393: 407 | B393: Funicular de Sant Joan | C393: Funicular | D393: funicular | E393: FGC | F393: FGC | G393: #A0522D | H393: Cataluña | I393: Barcelona | J393: Montserrat-Monestir; Sant Joan | K393: EST-MONTSERRAT; EST-SANTJOAN | M393: 407.geojson
A394: 408 | B394: Telefèric de Montjuïc | C394: Teleférico | D394: teleferico | E394: TMB | F394: TMB | G394: #FFD700 | H394: Cataluña | I394: Barcelona | J394: Parc de Montjuïc; Miramar; Castell | K394: EST-PARCDEMONTJUIC; EST-MIRAMAR; EST-CASTELLMONTSERRAT | M394: 408.geojson
A395: 409 | B395: Telecabina de la Coma del Clot | C395: Telecabina | D395: teleferico | E395: GPF | F395: GPF | G395: #006400 | H395: Cataluña | I395: Lleida | J395: Coma del Clot Inferior; Coma del Clot Superior | K395: EST-COMACLOTINF; EST-COMACLOTSUP | M395: 409.geojson
A396: 410 | B396: Telefèric de l'Estany Gento | C396: Teleférico | D396: teleferico | E396: La Vall Fosca | F396: La Vall Fosca | G396: #1E90FF | H396: Cataluña | I396: Lleida | J396: Sallente; Estany Gento | K396: EST-SALLENTE; EST-ESTANYGENTO | M396: 410.geojson
A397: 411 | B397: Telecabina de la Molina - Alp 2500 | C397: Telecabina | D397: teleferico | E397: FGC | F397: FGC | G397: #4169E1 | H397: Cataluña | I397: Girona | J397: La Molina; Alp 2500 | K397: EST-LAMOLINA; EST-ALP2500 | M397: 411.geojson
A398: 412 | B398: Telefèric del Port (Aeri del Port) | C398: Teleférico | D398: teleferico | E398: Port de Barcelona | F398: Port de Barcelona | G398: #00008B | H398: Cataluña | I398: Barcelona | J398: Sant Sebastià; Torre de Jaume I; Torre de Sant Sebastià | K398: EST-SANTSEBASTIA; EST-TORREJAUMEI; EST-TORRESANTSEBASTIA | M398: 412.geojson
A399: 413 | B399: Telecabina de Baquèira | C399: Telecabina | D399: teleferico | E399: Baqueira-Beret | F399: Baqueira-Beret | G399: #B22222 | H399: Cataluña | I399: Lleida | J399: Baquèira; Beret | K399: EST-BAQUEIRA; EST-BERET | M399: 413.geojson
A400: 414 | B400: Ascensor inclinat de Ciutat Meridiana | C400: Ascensor inclinat | D400: ascensor | E400: TMB | F400: TMB | G400: #8B0000 | H400: Cataluña | I400: Barcelona | J400: Ciutat Meridiana Inferior; Ciutat Meridiana Superior | K400: EST-CIUTATMERIDANAINF; EST-CIUTATMERIDANASUP | M400: 414.geojson
A401: 415 | B401: Ascensor inclinat de Queralt | C401: Ascensor inclinat | D401: ascensor | E401: Berga | F401: Berga | G401: #556B2F | H401: Cataluña | I401: Barcelona | J401: Berga Inferior; Berga Superior | K401: EST-BERGAINF; EST-BERGASUP | M401: 415.geojson
A402: 416 | B402: Ascensor inclinat de Cala Giverola | C402: Ascensor inclinat | D402: ascensor | E402: Tossa de Mar | F402: Tossa de Mar | G402: #2E8B57 | H402: Cataluña | I402: Girona | J402: Cala Giverola Inferior; Cala Giverola Superior | K402: EST-CALAGIVEROLAINF; EST-CALAGIVEROLASUP | M402: 416.geojson

Sheet Estaciones
A1: ID_Estación | B1: Nombre_Estación | C1: Municipio | D1: Provincia | E1: CCAA | F1: Líneas_ID_Operativas | G1: Líneas_Nombres_Operativas | H1: Coordenadas_OSM
A2: EST-SANFERNANDOCENTRO | B2: San Fernando-Centro | C2: San Fernando | D2: Cádiz | E2: Andalucía | F2: 236;238;351;368;372;377;394;397;401 | G2: C-1 Cádiz - Jerez de la Frontera;T1 TramBahía Cádiz - Chiclana;Regional R-2 Oviedo - Llanes - Santander;MD Regional 33/R11 Barcelona - Gerona - Figueras - Portbou;35c/R12 Hospitalet - Manresa - Lérida;Regional 48 Valencia - Cuenca - Madrid;MD 72 Sevilla - Huelva;Regional R-1 Ferrol - Ribadeo - Oviedo;MD 6 Vigo - Orense - Monforte - Ponferrada - León | H2: 36.47588,-6.19402
A3: EST-GAMA | B3: Gama | C3: Bárcena de Cicero | D3: Cantabria | E3: Cantabria | F3: 115;352;363;401 | G3: R4 Correo de La Robla León - Bilbao;Regional R-3 Santander - Marrón - Carranza - Bilbao;MD 23 León - Ponferrada - Monforte;MD 6 Vigo - Orense - Monforte - Ponferrada - León | H3: 43.42303,-3.52496
A4: EST-ZARAMILLO | B4: Zaramillo | C4: Güeñes | D4: Bizkaia | E4: País Vasco | F4: 115;259;352;353 | G4: R4 Correo de La Robla León - Bilbao;C-4 Bilbao La Concordia - Balmaseda-La Calzada;Regional R-3 Santander - Marrón - Carranza - Bilbao;Regional R-4 Bilbao - Mataporquera - León | H4: 43.23336,-3.01643
A5: EST-TOLOSAERDIA | B5: Tolosa-Erdia | C5: Tolosa | D5: Gipuzkoa | E5: País Vasco | F5: 273;397 | G5: C-1 Irun - Brinkola;Regional R-1 Ferrol - Ribadeo - Oviedo | H5: 43.13564,-2.07914
A6: EST-PUERTADEJEREZ | B6: Puerta de Jerez | C6: Sevilla | D6: Sevilla | E6: Andalucía | F6: 231;394 | G6: Metrocentro (T1) Luis de Morales - Archivo de Indias;MD 72 Sevilla - Huelva | H6: 37.38178,-5.99436
A7: EST-CANJAUMANDREU | B7: Can Jaumandreu | C7: Barcelona | D7: Barcelona | E7: Cataluña | F7: 191;192 | G7: T5 Glòries - Gorg;T6 Glòries - Estació de Sant Adrià | H7: 41.40802,2.19351
A8: EST-SANTIMAMISANMAMES | B8: Santimami-San Mamés | C8: Bilbao | D8: Bizkaia | E8: País Vasco | F8: 271 | G8: L2 Basauri - Kabiezes
A9: EST-EUSKALDUNA | B9: Euskalduna | C9: Bilbao | D9: Bizkaia | E9: País Vasco | F9: 267 | G9: TR Tranvía de Bilbao | H9: 43.26628,-2.94395
A10: EST-ARCDETRIOMF | B10: Arc de Triomf | C10: Barcelona | D10: Barcelona | E10: Cataluña | F10: 148;149;150;151;152;153 | G10: R1 Molins de Rei - Maçanet-Massanes;R2 Castelldefels - Granollers Centre;R2 Nord Aeroport - Maçanet-Massanes;R2 Sud Sant Vicenç de Calders - Barcelona-Estació de França;R3 L'Hospitalet de Llobregat - Puigcerdà / Latour-de-Carol;R4 Sant Vicenç de Calders - Manresa | H10: 41.39211,2.18091
A11: EST-PATERNA | B11: Paterna | C11: Paterna | D11: Valencia | E11: Comunidad Valenciana | F11: 205 | G11: L2 Llíria - Torrent Avinguda | H11: 39.49889,-0.44194
A12: EST-AUDITORITEATRENACIONAL | B12: Auditori | Teatre Nacional | C12: Barcelona | D12: Barcelona | E12: Cataluña | F12: 190 | G12: T4 Ciutadella - Estació de Sant Adrià | H12: 41.39755,2.18690
A13: EST-CCLAMARINA | B13: CC La Marina | C13: Finestrat | D13: Alicante | E13: Comunidad Valenciana | F13: 214;376;386;397 | G13: L1 Luceros - Benidorm;Regional Exprés 46 Valencia - Albacete - Alcázar;MD 57 Madrid - Alcázar - Albacete;Regional R-1 Ferrol - Ribadeo - Oviedo
A14: EST-MATIKOBILBAO | B14: Matiko-Bilbao | C14: Bilbao | D14: Bizkaia | E14: País Vasco | F14: 259;352;353 | G14: C-4 Bilbao La Concordia - Balmaseda-La Calzada;Regional R-3 Santander - Marrón - Carranza - Bilbao;Regional R-4 Bilbao - Mataporquera - León | H14: 43.26903,-2.92546
A15: EST-ARTXUBE | B15: Artxube | C15: Güeñes | D15: Bizkaia | E15: País Vasco | F15: 259 | G15: C-4 Bilbao La Concordia - Balmaseda-La Calzada | H15: 43.20102,-3.07164
A16: EST-LLERENA | B16: Llerena | C16: Llerena | D16: Badajoz | E16: Extremadura | F16: 56;396 | G16: MD 74 Mérida - Sevilla;Regional Exprés 74 Sevilla - Mérida | H16: 38.23775,-6.00962
A17: EST-GAVARRA | B17: Gavarra | C17: Cornellà de Llobregat | D17: Barcelona | E17: Cataluña | F17: 177 | G17: L5 Cornellà Centre - Vall d'Hebron | H17: 41.35799,2.07922
A18: EST-HOSPITALDEBELLVITGE | B18: Hospital de Bellvitge | C18: L'Hospitalet de Llobregat | D18: Barcelona | E18: Cataluña | F18: 170;171 | G18: S4 Plaça d'Espanya - Olesa de Montserrat;S8 Plaça d'Espanya - Martorell Enllaç | H18: 41.34465,2.10720
A19: EST-CAMPUSGUAJARA | B19: Campus Guajara | C19: San Cristóbal de La Laguna | D19: Santa Cruz de Tenerife | E19: Canarias | F19: 282 | G19: L1 Santa Cruz - La Laguna | H19: 28.46873,-16.30210
A20: EST-COLEGIO | B20: Colegio | C20: Zalla | D20: Bizkaia | E20: País Vasco | F20: 115;259 | G20: R4 Correo de La Robla León - Bilbao;C-4 Bilbao La Concordia - Balmaseda-La Calzada | H20: 43.21095,-3.13853
A21: EST-SIERRANEVADA | B21: Sierra Nevada | C21: Armilla | D21: Granada | E21: Andalucía | F21: 239 | G21: Línea 1 Albolote - Granada - Armilla | H21: 37.14399,-3.61404
A22: EST-MUNDAKA | B22: Mundaka | C22: Mundaka | D22: Bizkaia | E22: País Vasco | F22: 263 | G22: E4 Matiko - Bermeo | H22: 43.40889,-2.70104
A23: EST-CUATROVIENTOS | B23: Cuatro Vientos | C23: Madrid | D23: Madrid | E23: Madrid | F23: 14;125 | G23: Alvia Madrid - Cádiz;C-5 Móstoles El Soto - Atocha - Humanes | H23: 40.37790,-3.79197
A24: EST-GALAPAGARLANAVATA | B24: Galapagar-La Navata | C24: Galapagar | D24: Madrid | E24: Madrid | F24: 13;127 | G24: AVE Madrid - Galicia (Vigo);C-8a Santa María de la Alameda-Peguerinos - Villalba - Madrid-Chamartín - Guadalajara | H24: 40.60065,-3.98261
A25: EST-LODOSA | B25: Lodosa | C25: Lodosa | D25: Navarra | E25: Navarra | F25: 100;103;105 | G25: Regional Exprés Castejón - Logroño;MD 22 Zaragoza - Logroño;Regional Exprés Zaragoza - Miranda | H25: 42.38065,-2.07128
... A46: EST-LASARDANA | B46: La Sardana | C46: Esplugues de Llobregat | D46: Barcelona | E46: Cataluña | F46: 187;188;189 | G46: T1 Francesc Macià - Bon Viatge;T2 Francesc Macià - Llevant-Les Planes;T3 Francesc Macià - Sant Feliu | H46: 41.37279,2.08398
A47: EST-UNIVERSITATALICANTE | B47: Universitat | C47: San Vicente del Raspeig | D47: Alicante | E47: Comunidad Valenciana | F47: 215 | G47: =IFERROR(TEXTJOIN("; ",TRUE,XLOOKUP(TEXTSPLIT(F47,";"),Líneas!$A$2:$A$396,Líneas!$B$2:$B$396,"",0)),"")
A48: EST-VALDEPIELAGO | B48: Valdepiélago | C48: Valdepiélago | D48: León | E48: Castilla y León | F48: 115 | G48: R4 Correo de La Robla León - Bilbao | H48: 42.86494,-5.40324
A49: EST-HERRERA | B49: Herrera | C49: Donostia-San Sebastián | D49: Gipuzkoa | E49: País Vasco | F49: 273;365 | G49: C-1 Irun - Brinkola;MD Regional Exprés 25 Irún - Vitoria - Miranda de Ebro | H49: 43.31962,-1.93671
A50: EST-TRESCANTOS | B50: Tres Cantos | C50: Tres Cantos | D50: Madrid | E50: Madrid | F50: 124 | G50: C-4b Parla - Colmenar Viejo | H50: 40.59891,-3.71565
A51: EST-LOSOLVIDADOS | B51: Los Olvidados | C51: Zaragoza | D51: Zaragoza | E51: Aragón | F51: 242;388;394;397;399 | G51: L1 Mago de Oz - Avenida de la Academia;MD 60 Alcázar - Ciudad Real - Badajoz;MD 72 Sevilla - Huelva;Regional R-1 Ferrol - Ribadeo - Oviedo;MD 4 La Coruña - Lugo - Monforte - Orense | H51: 41.62253,-0.91855
A52: EST-ODONNELL | B52: O'Donnell | C52: Madrid | D52: Madrid | E52: Madrid | F52: 136;139 | G52: Línea 6 Circular;Línea 9 Paco de Lucía - Arganda del Rey | H52: 40.42220,-3.66906
A53: EST-ARBIDE | B53: Arbide | C53: Arrankudiaga | D53: Bizkaia | E53: País Vasco | F53: 258 | G53: C-3 Bilbao Abando - Orduña | H53: 43.16323,-2.92766
A54: EST-PORTALDEFORONDA | B54: Portal de Foronda | C54: Vitoria-Gasteiz | D54: Álava | E54: País Vasco | F54: 265 | G54: Eje Abetxuko-Unibertsitatea
A55: EST-NAVALPERAL | B55: Navalperal | C55: Navalperal de Pinares | D55: Ávila | E55: Castilla y León | F55: 65;357;380 | G55: MD 13 Madrid - Salamanca;MD 16 Valladolid - Ávila - Madrid;Regional 51 Madrid - Ávila (Se requiere transbordo en El Escorial) | H55: 40.59093,-4.40863
A56: EST-LUISDEMORALES | B56: Luis de Morales | C56: Sevilla | D56: Sevilla | E56: Andalucía | F56: 231 | G56: Metrocentro (T1) Luis de Morales - Archivo de Indias | H56: 37.38381,-5.97277
A57: EST-FUENGIROLA | B57: Fuengirola | C57: Fuengirola | D57: Málaga | E57: Andalucía | F57: 232 | G57: C-1 Málaga Centro-Alameda - Fuengirola | H57: 36.54181,-4.62398
A58: EST-VILANOVADELABARCA | B58: Vilanova de la Barca | C58: Vilanova de la Barca | D58: Lleida | E58: Cataluña | F58: 161;162 | G58: RL1 Lleida Pirineus - Balaguer;RL2 Lleida Pirineus - La Pobla de Segur | H58: 41.68736,0.72791
A59: EST-ARMILLA | B59: Armilla | C59: Armilla | D59: Granada | E59: Andalucía | F59: 239 | G59: Línea 1 Albolote - Granada - Armilla | H59: 37.14372,-3.62715
A60: EST-LARODA | B60: La Roda | C60: La Roda | D60: Albacete | E60: Castilla-La Mancha | F60: 78;85;117;370;375;376;386 | G60: MD 43 Alicante - Ciudad Real;MD 57 Madrid - Albacete;MD Línea 45/46 Madrid - Valencia;Regional Exprés 35a/R13 Barcelona - Valls - Lérida;MD 45 Alicante - Albacete - Alcázar - Ciudad Real;Regional Exprés 46 Valencia - Albacete - Alcázar;MD 57 Madrid - Alcázar - Albacete | H60: 39.19932,-2.16292
...
